Workbook

Sheet Read Me
A1: Debt Management Module - Features, Stories and Tasks
A2: Implementation backlog derived from Debt_Management_Maker_Checker_Approver_Design.docx. Acceptance criteria are written in strict Given-When-Then format.
A4: Backlog measure | B4: Value | D4: Workbook structure
A5: Features | B5: =COUNTA(Features!$C$5:$C$200) -> 78 | D5: Features | E5: Feature catalogue with source references, dependencies and formula-driven story/task counts.
A6: User stories | B6: =COUNTA(Backlog!$E$5:$E$1000) -> 680 | D6: Backlog | E6: One row per user story, with actor, workflow, source requirement and Given-When-Then acceptance criteria.
A7: Implementation tasks | B7: =COUNTA(Tasks!$A$5:$A$4000) -> 3100 | D7: Tasks | E7: Implementation tasks mapped to every story, including UX, API, validation, workflow, registers, integration and testing.
A8: Acceptance criteria | B8: 2933 | D8: Data Objects | E8: M01-M43 masters, C01-C13 configurations and R01-R24 registers with fields, values, triggers and actions.
A9: Master / configuration objects | B9: 56 | D9: FRS Traceability | E9: Original 43 FRS rows plus the additional loan/WMA elaborations mapped to feature and story IDs.
A10: Registers | B10: 24 | D10: Lists | E10: Controlled values used for status, priority, phase and task type.
D11: Source convention | E11: Fxx = functional workflow; ACxx = accounting workflow; Mxx/Cxx/Rxx retain the document identifiers.
A13: How to use the backlog
A14: 1 | B14: Filter Features by phase and priority to agree release scope.
A15: 2 | B15: Review each Backlog story and confirm the Given-When-Then criteria with business, accounting and technical owners.
A16: 3 | B16: Assign owners and estimates to Tasks; Status is intentionally set to Not Started.
A17: 4 | B17: Use Feature ID, Story ID and M/C/R references to trace every item back to the source document.
A18: 5 | B18: Treat Project/Program data as an existing integrated source; do not create a duplicate project master in this module.
A19: 6 | B19: Retain Maker-Checker-Approver decisions, effective versions, corrections and destination outcomes in R19/R20.

Sheet Features
A1: Feature Catalogue
A2: Functional, accounting and data-foundation features with traceability and formula-driven coverage counts.
A4: Epic Section | B4: Epic | C4: Feature ID | D4: Feature | E4: Purpose / Scope | F4: Source Section | G4: Story Count | H4: Task Count | I4: FRS Sl. Nos. | J4: Master / Config Refs | K4: Register Refs | L4: Dependencies | M4: Priority | N4: Suggested Phase | O4: Coverage
A5: 0 | B5: Data Foundation and Traceability | C5: DF01 | D5: Master data and shared-source integration | E5: Implement or integrate M01-M43 with effective dates, ownership, validations and F01 approval controls. | F5: 8-9 / 13 | G5: =COUNTIF(Backlog!$C$5:$C$684,C5) -> 43 | H5: =COUNTIF(Tasks!$C$5:$C$3104,C5) -> 215 | J5: M01, M02, M03, M04, M05, M06, M07, M08, M09, M10, M11, M12, M13, M14, M15, M16, M17, M18, M19, M20, M21, M22, M23, M24, M25, M26, M27, M28, M29, M30, M31, M32, M33, M34, M35, M36, M37, M38, M39, M40, M41, M42, M43 | L5: F01-F04, AC01, C01, R19-R20 | M5: Must | N5: 1 - Foundation and Configuration | O5: =IF(AND(G5>0,H5>0),"Covered","Gap") -> Covered
A6: 0 | B6: Data Foundation and Traceability | C6: DF02 | D6: Effective-dated configuration and control tables | E6: Implement C01-C13 as tested, versioned and approved control tables used by functions and calculations. | F6: 8-9 / 13 | G6: =COUNTIF(Backlog!$C$5:$C$684,C6) -> 13 | H6: =COUNTIF(Tasks!$C$5:$C$3104,C6) -> 65 | J6: C01, C02, C03, C04, C05, C06, C07, C08, C09, C10, C11, C12, C13 | L6: F01-F04, AC01, C01, R19-R20 | M6: Must | N6: 1 - Foundation and Configuration | O6: =IF(AND(G6>0,H6>0),"Covered","Gap") -> Covered
A7: 0 | B7: Data Foundation and Traceability | C7: DF03 | D7: Event registers, balances and traceability | E7: Implement R01-R24 as event-led registers with immutable movements, derived balances and end-to-end traceability. | F7: 8-9 / 13 | G7: =COUNTIF(Backlog!$C$5:$C$684,C7) -> 24 | H7: =COUNTIF(Tasks!$C$5:$C$3104,C7) -> 120 | K7: R01, R02, R03, R04, R05, R06, R07, R08, R09, R10, R11, R12, R13, R14, R15, R16, R17, R18, R19, R20, R21, R22, R23, R24 | L7: F01-F04, AC01, C01, R19-R20 | M7: Must | N7: 1 - Foundation and Configuration | O7: =IF(AND(G7>0,H7>0),"Covered","Gap") -> Covered
A8: 1 | B8: 1. General | C8: F01 | D8: Maintain master values | E8: Masters / source references: M01-M35; shared values remain in their owning modules. | F8: 1.5.1 | G8: =COUNTIF(Backlog!$C$5:$C$684,C8) -> 8 | H8: =COUNTIF(Tasks!$C$5:$C$3104,C8) -> 36 | J8: M01, M35 | L8: M01, M35 | M8: Must | N8: 1 - Foundation and Configuration | O8: =IF(AND(G8>0,H8>0),"Covered","Gap") -> Covered
A9: 1 | B9: 1. General | C9: F02 | D9: Configure Maker, Checker and Approver routing | E9: Masters / source references: M01, M04, M10; C01. | F9: 1.5.2 | G9: =COUNTIF(Backlog!$C$5:$C$684,C9) -> 8 | H9: =COUNTIF(Tasks!$C$5:$C$3104,C9) -> 36 | J9: C01, M01, M04, M10 | L9: C01, M01, M04, M10 | M9: Must | N9: 1 - Foundation and Configuration | O9: =IF(AND(G9>0,H9>0),"Covered","Gap") -> Covered
A10: 1 | B10: 1. General | C10: F03 | D10: Maintain exchange and interest rates | E10: Masters / source references: M04, M18, M21; C02. | F10: 1.5.3 | G10: =COUNTIF(Backlog!$C$5:$C$684,C10) -> 8 | H10: =COUNTIF(Tasks!$C$5:$C$3104,C10) -> 36 | I10: 35 | J10: C02, M04, M18, M21 | L10: C02, M04, M18, M21 | M10: Must | N10: 1 - Foundation and Configuration | O10: =IF(AND(G10>0,H10>0),"Covered","Gap") -> Covered
A11: 1 | B11: 1. General | C11: F04 | D11: Configure CoA mapping and accounting rules | E11: Masters / source references: M07, M12, M23, M32-M33; C05. These functions are reused from each applicable instrument. Project/Program IDs and source-owned details come from the existing Project/Program list. CoA/HoA and accounting entries use the existing chart and common accounting service. | F11: 1.5.4 | G11: =COUNTIF(Backlog!$C$5:$C$684,C11) -> 8 | H11: =COUNTIF(Tasks!$C$5:$C$3104,C11) -> 36 | I11: 36 | J11: C05, M07, M12, M23, M32, M33 | L11: C05, M07, M12, M23, M32, M33 | M11: Must | N11: 1 - Foundation and Configuration | O11: =IF(AND(G11>0,H11>0),"Covered","Gap") -> Covered
A12: 6 | B12: 6. Accounting by instrument type | C12: AC01 | D12: Accounting masters and configuration | E12: Register behavior: R01-R06 are current-position views backed by transaction history; R07-R19 retain event rows and balances; R20 is append-only audit history. Approved corrections add linked records or versions. Deactivation or closure must not delete financial history. | F12: 6.1.1 | G12: =COUNTIF(Backlog!$C$5:$C$684,C12) -> 8 | H12: =COUNTIF(Tasks!$C$5:$C$3104,C12) -> 36 | I12: 36 | J12: C05, C06 | K12: R01, R06, R07, R18, R19, R20 | L12: C05, C06, R01, R06, R07, R18, R19, R20 | M12: Must | N12: 1 - Foundation and Configuration | O12: =IF(AND(G12>0,H12>0),"Covered","Gap") -> Covered
A13: 6 | B13: 6. Accounting by instrument type | C13: AC02 | D13: First-time opening balances and migrated instruments | E13: Implement the controlled First-time opening balances and migrated instruments capability described in the source document. | F13: 6.1.5 | G13: =COUNTIF(Backlog!$C$5:$C$684,C13) -> 8 | H13: =COUNTIF(Tasks!$C$5:$C$3104,C13) -> 36 | J13: C05 | K13: R01, R17, R18, R20 | L13: C05, R01, R17, R18, R20 | M13: Must | N13: 1 - Foundation and Configuration | O13: =IF(AND(G13>0,H13>0),"Covered","Gap") -> Covered
A14: 1 | B14: 1. General | C14: F06 | D14: Maintain supporting documents | E14: Masters / source references: M31; approved or draft instrument/request reference. | F14: 1.6.1 | G14: =COUNTIF(Backlog!$C$5:$C$684,C14) -> 8 | H14: =COUNTIF(Tasks!$C$5:$C$3104,C14) -> 36 | J14: M31 | L14: M31 | M14: Must | N14: 2 - Core Debt Recording and Servicing | O14: =IF(AND(G14>0,H14>0),"Covered","Gap") -> Covered
A15: 1 | B15: 1. General | C15: F07 | D15: Link an existing Project or Program | E15: Masters / source references: M01, M04-M07, M11; C04, C06. | F15: 1.6.2 | G15: =COUNTIF(Backlog!$C$5:$C$684,C15) -> 8 | H15: =COUNTIF(Tasks!$C$5:$C$3104,C15) -> 36 | I15: 32, 34 | J15: C04, C06, M01, M04, M07, M11 | L15: C04, C06, M01, M04, M07, M11 | M15: Must | N15: 2 - Core Debt Recording and Servicing | O15: =IF(AND(G15>0,H15>0),"Covered","Gap") -> Covered
A16: 1 | B16: 1. General | C16: F25 | D16: Post debt accounting and reconcile | E16: Masters / source references: M04, M07, M09, M23, M32-M33; C05; source events and common GL. Apply each function only to the relevant instrument event. Loans use drawdowns, repayments or recoveries. Securities use evidenced issue/settlement and coupon/redemption events. Grants use receipts, transfers, utilisation and contractual refunds, not ordinary loan-principal/interest schedules. Guarantees use borrower monitoring, fees and an approved invocation obligation; they are not direct borrowing merely because they are recorded. | F16: 1.6.4 | G16: =COUNTIF(Backlog!$C$5:$C$684,C16) -> 8 | H16: =COUNTIF(Tasks!$C$5:$C$3104,C16) -> 36 | I16: 9, 20, 36 | J16: C05, M04, M07, M09, M23, M32, M33 | L16: C05, M04, M07, M09, M23, M32, M33 | M16: Must | N16: 2 - Core Debt Recording and Servicing | O16: =IF(AND(G16>0,H16>0),"Covered","Gap") -> Covered
A17: 1 | B17: 1. General | C17: F16 | D17: Prepare disbursement forecasts | E17: Masters / source references: M01-M06, M09, M25; approved instrument; C04. | F17: 1.7.1 | G17: =COUNTIF(Backlog!$C$5:$C$684,C17) -> 8 | H17: =COUNTIF(Tasks!$C$5:$C$3104,C17) -> 36 | I17: 19, 22 | J17: C04, M01, M06, M09, M25 | L17: C04, M01, M06, M09, M25 | M17: Must | N17: 2 - Core Debt Recording and Servicing | O17: =IF(AND(G17>0,H17>0),"Covered","Gap") -> Covered
A18: 1 | B18: 1. General | C18: F17 | D18: Record actual disbursements and funding receipts | E18: Masters / source references: M01-M09, M25, M31; instrument/allocation; C02, C04, C06. | F18: 1.7.2 | G18: =COUNTIF(Backlog!$C$5:$C$684,C18) -> 8 | H18: =COUNTIF(Tasks!$C$5:$C$3104,C18) -> 36 | I18: 21, 33 | J18: C02, C04, C06, M01, M09, M25, M31 | L18: C02, C04, C06, M01, M09, M25, M31 | M18: Must | N18: 2 - Core Debt Recording and Servicing | O18: =IF(AND(G18>0,H18>0),"Covered","Gap") -> Covered
A19: 1 | B19: 1. General | C19: F18 | D19: Generate debt-service schedules | E19: Masters / source references: M04, M09, M17-M24; approved terms/drawdowns; C02-C03. | F19: 1.7.3 | G19: =COUNTIF(Backlog!$C$5:$C$684,C19) -> 8 | H19: =COUNTIF(Tasks!$C$5:$C$3104,C19) -> 36 | I19: 2, 19, 22, 35 | J19: C02, C03, M04, M09, M17, M24 | L19: C02, C03, M04, M09, M17, M24 | M19: Must | N19: 2 - Core Debt Recording and Servicing | O19: =IF(AND(G19>0,H19>0),"Covered","Gap") -> Covered
A20: 1 | B20: 1. General | C20: F19 | D20: Create repayment Claim Requests and record settlement | E20: Masters / source references: M02, M04, M06-M09, M23, M31; schedule; existing claim/treasury services. | F20: 1.7.4 | G20: =COUNTIF(Backlog!$C$5:$C$684,C20) -> 8 | H20: =COUNTIF(Tasks!$C$5:$C$3104,C20) -> 36 | I20: 9, 20, 21 | J20: M02, M04, M06, M09, M23, M31 | L20: M02, M04, M06, M09, M23, M31 | M20: Must | N20: 2 - Core Debt Recording and Servicing | O20: =IF(AND(G20>0,H20>0),"Covered","Gap") -> Covered
A21: 1 | B21: 1. General | C21: F21 | D21: Manage arrears, penalties and waivers | E21: Masters / source references: M02, M04, M09, M23-M24, M31; schedule and actuals; C03. | F21: 1.7.5 | G21: =COUNTIF(Backlog!$C$5:$C$684,C21) -> 8 | H21: =COUNTIF(Tasks!$C$5:$C$3104,C21) -> 36 | J21: C03, M02, M04, M09, M23, M24, M31 | L21: C03, M02, M04, M09, M23, M24, M31 | M21: Must | N21: 2 - Core Debt Recording and Servicing | O21: =IF(AND(G21>0,H21>0),"Covered","Gap") -> Covered
A22: 1 | B22: 1. General | C22: F30 | D22: Close, cancel or reopen an instrument | E22: Masters / source references: M09, M31; instrument, schedules, balances and linked transactions. Shared outputs should support instrument-type and subtype filters, single instruments and the full portfolio. Show direct debt, government lending, grants and contingent guarantees separately before presenting any explicitly defined aggregation. | F22: 1.7.6 | G22: =COUNTIF(Backlog!$C$5:$C$684,C22) -> 8 | H22: =COUNTIF(Tasks!$C$5:$C$3104,C22) -> 36 | J22: M09, M31 | L22: M09, M31 | M22: Must | N22: 2 - Core Debt Recording and Servicing | O22: =IF(AND(G22>0,H22>0),"Covered","Gap") -> Covered
A23: 1 | B23: 1. General | C23: F27 | D23: Generate standard and international reports | E23: Masters / source references: M03-M04, M09, M12-M16, M34; C07. | F23: 1.8.2 | G23: =COUNTIF(Backlog!$C$5:$C$684,C23) -> 8 | H23: =COUNTIF(Tasks!$C$5:$C$3104,C23) -> 36 | I23: 37, 38, 39, 40, 41, 42, 43 | J23: C07, M03, M04, M09, M12, M16, M34 | L23: C07, M03, M04, M09, M12, M16, M34 | M23: Must | N23: 2 - Core Debt Recording and Servicing | O23: =IF(AND(G23>0,H23>0),"Covered","Gap") -> Covered
A24: 1 | B24: 1. General | C24: F29 | D24: Configure dashboards, alerts and escalation | E24: Masters / source references: M01, M04, M09-M10, M35; C08. | F24: 1.8.4 | G24: =COUNTIF(Backlog!$C$5:$C$684,C24) -> 8 | H24: =COUNTIF(Tasks!$C$5:$C$3104,C24) -> 36 | I24: 37, 38, 39, 40, 41, 42, 43 | J24: C08, M01, M04, M09, M10, M35 | L24: C08, M01, M04, M09, M10, M35 | M24: Must | N24: 2 - Core Debt Recording and Servicing | O24: =IF(AND(G24>0,H24>0),"Covered","Gap") -> Covered
A25: 2 | B25: 2. Loans | C25: F05-D | D25: Domestic loans | E25: Masters / source references: M01-M07, M12-M14, M17-M25, M31; C03-C05. | F25: 2.1 | G25: =COUNTIF(Backlog!$C$5:$C$684,C25) -> 8 | H25: =COUNTIF(Tasks!$C$5:$C$3104,C25) -> 36 | I25: 1, 2 | J25: C03, C05, M01, M07, M12, M14, M17, M25, M31 | L25: C03, C05, M01, M07, M12, M14, M17, M25, M31 | M25: Must | N25: 2 - Core Debt Recording and Servicing | O25: =IF(AND(G25>0,H25>0),"Covered","Gap") -> Covered
A26: 2 | B26: 2. Loans | C26: F05-E | D26: External loans | E26: Masters / source references: M01-M07, M12-M14, M17-M25, M31; C03-C05. These are M14 arrangements, not substitutes for the Domestic/External classification. Retain links to the source instrument and its classification, while maintaining each subsidiary agreement and borrower-recovery obligation separately. | F26: 2.2 | G26: =COUNTIF(Backlog!$C$5:$C$684,C26) -> 8 | H26: =COUNTIF(Tasks!$C$5:$C$3104,C26) -> 36 | I26: 1, 2 | J26: C03, C05, M01, M07, M12, M14, M17, M25, M31 | L26: C03, C05, M01, M07, M12, M14, M17, M25, M31 | M26: Must | N26: 2 - Core Debt Recording and Servicing | O26: =IF(AND(G26>0,H26>0),"Covered","Gap") -> Covered
A27: 2 | B27: 2. Loans | C27: F20 | D27: Borrower recoveries | E27: Masters / source references: M02, M04, M07-M09, M23, M31; subsidiary/government loan; C06. | F27: 2.4 | G27: =COUNTIF(Backlog!$C$5:$C$684,C27) -> 8 | H27: =COUNTIF(Tasks!$C$5:$C$3104,C27) -> 36 | I27: 9, 21 | J27: C06, M02, M04, M07, M09, M23, M31 | L27: C06, M02, M04, M07, M09, M23, M31 | M27: Must | N27: 2 - Core Debt Recording and Servicing | O27: =IF(AND(G27>0,H27>0),"Covered","Gap") -> Covered
A28: 6 | B28: 6. Accounting by instrument type | C28: AC03 | D28: Domestic loan accounting | E28: Source functions / masters: F05-D, F17-F19, F21-F22, F25; M07, M13, M23, M32-M33; C02-C05 | F28: 6.2.1 | G28: =COUNTIF(Backlog!$C$5:$C$684,C28) -> 8 | H28: =COUNTIF(Tasks!$C$5:$C$3104,C28) -> 36 | I28: 1, 2, 9, 20, 21, 33 | J28: C02, C05, M07, M13, M23, M32, M33 | K28: R01, R06, R07, R10, R12, R14, R17, R18, R20 | L28: C02, C05, M07, M13, M23, M32, M33, R01, R06, R07, R10, R12, R14, R17, R18, R20 | M28: Must | N28: 2 - Core Debt Recording and Servicing | O28: =IF(AND(G28>0,H28>0),"Covered","Gap") -> Covered
A29: 6 | B29: 6. Accounting by instrument type | C29: AC04 | D29: External loan accounting | E29: Source functions / masters: F05-E, F17-F19, F22, F25; M03-M04, M07, M25; C02, C05-C06 | F29: 6.2.2 | G29: =COUNTIF(Backlog!$C$5:$C$684,C29) -> 8 | H29: =COUNTIF(Tasks!$C$5:$C$3104,C29) -> 36 | I29: 1, 2, 9, 20, 21, 33 | J29: C02, C05, C06, M03, M04, M07, M25 | K29: R01, R06, R10, R12, R14, R17, R18, R20 | L29: C02, C05, C06, M03, M04, M07, M25, R01, R06, R10, R12, R14, R17, R18, R20 | M29: Must | N29: 2 - Core Debt Recording and Servicing | O29: =IF(AND(G29>0,H29>0),"Covered","Gap") -> Covered
A30: 6 | B30: 6. Accounting by instrument type | C30: AC22 | D30: Cross-instrument adjustments, reconciliation and close | E30: IPSAS 41 addresses classification and measurement of financial instruments and includes public-sector guidance for concessionary loans and financial guarantees. Use it only if adopted by the applicable authority. IPSASB - IPSAS 41, Financial Instruments IPSASB - Public-sector financial instruments guidance IPSAS 47 distinguishes revenue accounting models according to whether a binding arrangement exists. IPSAS 48 provides guidance for transfer expenses. These references explain why the grant and on-granting rules require explicit policy configuration. IPSASB - IPSAS 47, Revenue IPSASB - IPSAS 48, Transfer Expenses For comparison, New Zealand PBE IPSAS 41, paragraphs 45(c) and AG131-AG132, explicitly addresses financial-guarantee recognition and measurement. It supports the design distinction between guarantee exposure and a recognised guarantee liability; it is not assumed to govern this implementation. XRB - PBE IPSAS 41, Financial Instruments | F30: 6.6 | G30: =COUNTIF(Backlog!$C$5:$C$684,C30) -> 8 | H30: =COUNTIF(Tasks!$C$5:$C$3104,C30) -> 36 | I30: 35 | K30: R01, R20 | L30: R01, R20 | M30: Must | N30: 2 - Core Debt Recording and Servicing | O30: =IF(AND(G30>0,H30>0),"Covered","Gap") -> Covered
A31: 1 | B31: 1. General | C31: F24 | D31: Monitor Project/Program expenditure and utilisation | E31: Masters / source references: M01, M05-M07, M11, M25; C04, C06; owning project/financial systems. | F31: 1.6.3 | G31: =COUNTIF(Backlog!$C$5:$C$684,C31) -> 8 | H31: =COUNTIF(Tasks!$C$5:$C$3104,C31) -> 36 | I31: 32, 33, 34, 36 | J31: C04, C06, M01, M05, M07, M11, M25 | L31: C04, C06, M01, M05, M07, M11, M25 | M31: Should | N31: 3 - Extended Instruments and Accounting | O31: =IF(AND(G31>0,H31>0),"Covered","Gap") -> Covered
A32: 2 | B32: 2. Loans | C32: F08 | D32: Record back-to-back lending | E32: Masters / source references: M01-M07, M14, M17-M24, M31; parent loan; C03-C04. | F32: 2.3.1 | G32: =COUNTIF(Backlog!$C$5:$C$684,C32) -> 8 | H32: =COUNTIF(Tasks!$C$5:$C$3104,C32) -> 36 | I32: 3 | J32: C03, C04, M01, M07, M14, M17, M24, M31 | L32: C03, C04, M01, M07, M14, M17, M24, M31 | M32: Should | N32: 3 - Extended Instruments and Accounting | O32: =IF(AND(G32>0,H32>0),"Covered","Gap") -> Covered
A33: 2 | B33: 2. Loans | C33: F09 | D33: Split a loan among sub-borrowers | E33: Masters / source references: M01-M07, M14, M17-M24, M31; parent loan; C03-C04. | F33: 2.3.2 | G33: =COUNTIF(Backlog!$C$5:$C$684,C33) -> 8 | H33: =COUNTIF(Tasks!$C$5:$C$3104,C33) -> 36 | I33: 4 | J33: C03, C04, M01, M07, M14, M17, M24, M31 | L33: C03, C04, M01, M07, M14, M17, M24, M31 | M33: Should | N33: 3 - Extended Instruments and Accounting | O33: =IF(AND(G33>0,H33>0),"Covered","Gap") -> Covered
A34: 2 | B34: 2. Loans | C34: F10 | D34: Create and maintain a loan pool | E34: Masters / source references: M01-M07, M14, M31; source instruments; C04. | F34: 2.3.3 | G34: =COUNTIF(Backlog!$C$5:$C$684,C34) -> 8 | H34: =COUNTIF(Tasks!$C$5:$C$3104,C34) -> 36 | I34: 5 | J34: C04, M01, M07, M14, M31 | L34: C04, M01, M07, M14, M31 | M34: Should | N34: 3 - Extended Instruments and Accounting | O34: =IF(AND(G34>0,H34>0),"Covered","Gap") -> Covered
A35: 2 | B35: 2. Loans | C35: F14 | D35: Record government loans from budget | E35: Masters / source references: M01-M09, M14, M17-M24, M31; existing budget allocation. | F35: 2.3.4 | G35: =COUNTIF(Backlog!$C$5:$C$684,C35) -> 8 | H35: =COUNTIF(Tasks!$C$5:$C$3104,C35) -> 36 | I35: 8 | J35: M01, M09, M14, M17, M24, M31 | L35: M01, M09, M14, M17, M24, M31 | M35: Should | N35: 3 - Extended Instruments and Accounting | O35: =IF(AND(G35>0,H35>0),"Covered","Gap") -> Covered
A36: 2 | B36: 2. Loans | C36: F22 | D36: Loan restructuring | E36: Masters / source references: M04, M09, M23, M28-M29, M31; loan terms and balances. | F36: 2.5 | G36: =COUNTIF(Backlog!$C$5:$C$684,C36) -> 8 | H36: =COUNTIF(Tasks!$C$5:$C$3104,C36) -> 36 | I36: 23, 24, 25, 26 | J36: M04, M09, M23, M28, M29, M31 | L36: M04, M09, M23, M28, M29, M31 | M36: Should | N36: 3 - Extended Instruments and Accounting | O36: =IF(AND(G36>0,H36>0),"Covered","Gap") -> Covered
A37: 3 | B37: 3. Debt securities | C37: F15-TB | D37: Treasury bills | E37: Masters / source references: M01-M04, M07-M09, M12-M13, M15-M19, M23, M31. | F37: 3.1 | G37: =COUNTIF(Backlog!$C$5:$C$684,C37) -> 8 | H37: =COUNTIF(Tasks!$C$5:$C$3104,C37) -> 36 | I37: 10, 11, 12, 17 | J37: M01, M04, M07, M09, M12, M13, M15, M19, M23, M31 | L37: M01, M04, M07, M09, M12, M13, M15, M19, M23, M31 | M37: Should | N37: 3 - Extended Instruments and Accounting | O37: =IF(AND(G37>0,H37>0),"Covered","Gap") -> Covered
A38: 3 | B38: 3. Debt securities | C38: F15-BD | D38: Bonds | E38: Masters / source references: M01-M04, M07-M09, M12-M13, M15-M19, M23, M31. | F38: 3.2 | G38: =COUNTIF(Backlog!$C$5:$C$684,C38) -> 8 | H38: =COUNTIF(Tasks!$C$5:$C$3104,C38) -> 36 | I38: 10, 11, 13, 17 | J38: M01, M04, M07, M09, M12, M13, M15, M19, M23, M31 | L38: M01, M04, M07, M09, M12, M13, M15, M19, M23, M31 | M38: Should | N38: 3 - Extended Instruments and Accounting | O38: =IF(AND(G38>0,H38>0),"Covered","Gap") -> Covered
A39: 3 | B39: 3. Debt securities | C39: F15-TR | D39: Tax/Reserve certificates | E39: Masters / source references: M01-M04, M07-M09, M12-M13, M15-M19, M23, M31. | F39: 3.3 | G39: =COUNTIF(Backlog!$C$5:$C$684,C39) -> 8 | H39: =COUNTIF(Tasks!$C$5:$C$3104,C39) -> 36 | I39: 10, 11, 14, 17 | J39: M01, M04, M07, M09, M12, M13, M15, M19, M23, M31 | L39: M01, M04, M07, M09, M12, M13, M15, M19, M23, M31 | M39: Should | N39: 3 - Extended Instruments and Accounting | O39: =IF(AND(G39>0,H39>0),"Covered","Gap") -> Covered
A40: 3 | B40: 3. Debt securities | C40: F15-PN | D40: Promissory notes | E40: Masters / source references: M01-M04, M07-M09, M12-M13, M15-M19, M23, M31. | F40: 3.4 | G40: =COUNTIF(Backlog!$C$5:$C$684,C40) -> 8 | H40: =COUNTIF(Tasks!$C$5:$C$3104,C40) -> 36 | I40: 10, 11, 15, 17 | J40: M01, M04, M07, M09, M12, M13, M15, M19, M23, M31 | L40: M01, M04, M07, M09, M12, M13, M15, M19, M23, M31 | M40: Should | N40: 3 - Extended Instruments and Accounting | O40: =IF(AND(G40>0,H40>0),"Covered","Gap") -> Covered
A41: 3 | B41: 3. Debt securities | C41: F15-CP | D41: Commercial paper | E41: Masters / source references: M01-M04, M07-M09, M12-M13, M15-M19, M23, M31. | F41: 3.5 | G41: =COUNTIF(Backlog!$C$5:$C$684,C41) -> 8 | H41: =COUNTIF(Tasks!$C$5:$C$3104,C41) -> 36 | I41: 10, 11, 16, 17 | J41: M01, M04, M07, M09, M12, M13, M15, M19, M23, M31 | L41: M01, M04, M07, M09, M12, M13, M15, M19, M23, M31 | M41: Should | N41: 3 - Extended Instruments and Accounting | O41: =IF(AND(G41>0,H41>0),"Covered","Gap") -> Covered
...

Sheet Backlog
A1: User Story Backlog
A2: Every story is mapped to the source feature and includes function-specific Given-When-Then acceptance criteria.
A4: Epic Section | B4: Epic | C4: Feature ID | D4: Feature | E4: Story ID | F4: Actor | G4: Workflow | H4: User Story | I4: Acceptance Criteria (Given-When-Then) | J4: Source Requirement | K4: Master / Config Refs | L4: Register Refs | M4: FRS Sl. Nos. | N4: Dependencies | O4: Priority | P4: Suggested Phase | Q4: Source Section | R4: Backlog Status
A5: 0 | B5: Data Foundation and Traceability | C5: DF01 | D5: Master data and shared-source integration | E5: DF01-US01 | F5: Configuration Administrator | G5: Data foundation | H5: As a Configuration Administrator, I want to maintain or integrate M01 - Organisation / agency / existing organisation; organisation_hierarchy, so that approved debt functions use one controlled and traceable value source. | I5: AC1. Given M01 is implemented, when a value is created, fetched or synchronised, then the following ownership shall be enforced: Existing shared source. AC2. Given a record is entered or received, when it is validated, then every field, required/conditional flag, permitted value and validation documented for M01 in the Data Objects sheet shall be enforced. AC3. Given the object is source-owned, when Debt Management fetches or displays the record, then the original source ID shall be reused, source attributes shall remain read-only and no duplicate master shall be created. AC4. Given a debt-specific value is created or modified, when it is submitted for activation, then F01 Maker-Checker-Approver, effective dates, active/inactive status and immutable history shall apply before the value is used. AC5. Given an approved value becomes effective, when an applicable function loads its selectors or validations, then the value shall be available only in the applicable functions: Derived from Annexure B and referenced feature metadata. | J5: Effective-dated master/reference data; source-owned IDs are reused where identified. organisation_id (FK) | R | Existing ORG001; do not generate a second agency ID. organisation_type (FK) | R | Approved source value: Ministry, Treasury, Agency or Local Government. parent_organisation_id (FK) | C | Existing hierarchy parent; nullable at root or where source permits. hierarchy_level / path (source fields) | R | Source-defined levels, not a hard-coded government structure. country_id (FK M03) | R | Organisation country from source. validity / source_status (source fields) | R | Read-only eligibility for new requests. Create/modify through F01 under Maker-Checker-Approver; approved changes apply prospectively and preserve historical references. | K5: M01 | N5: F01-F04, AC01, C01, R19-R20 | O5: Must | P5: 1 - Foundation and Configuration | Q5: Section 8.3.1 | R5: Ready for Review
A6: 0 | B6: Data Foundation and Traceability | C6: DF01 | D6: Master data and shared-source integration | E6: DF01-US02 | F6: Configuration Administrator | G6: Data foundation | H6: As a Configuration Administrator, I want to maintain or integrate M02 - Counterparty and role / existing counterparty; counterparty_role, so that approved debt functions use one controlled and traceable value source. | I6: AC1. Given M02 is implemented, when a value is created, fetched or synchronised, then the following ownership shall be enforced: Existing shared source. AC2. Given a record is entered or received, when it is validated, then every field, required/conditional flag, permitted value and validation documented for M02 in the Data Objects sheet shall be enforced. AC3. Given the object is source-owned, when Debt Management fetches or displays the record, then the original source ID shall be reused, source attributes shall remain read-only and no duplicate master shall be created. AC4. Given a debt-specific value is created or modified, when it is submitted for activation, then F01 Maker-Checker-Approver, effective dates, active/inactive status and immutable history shall apply before the value is used. AC5. Given an approved value becomes effective, when an applicable function loads its selectors or validations, then the value shall be available only in the applicable functions: Derived from Annexure B and referenced feature metadata. | J6: Effective-dated master/reference data; source-owned IDs are reused where identified. counterparty_id / legal_name (FK / text) | R | CP001 / Example Development Bank; source-owned. resident_country_id (FK M03) | R | Country of residence used by approved classification rule. counterparty_category (source FK) | R | Government, Public corporation, Bank, Multilateral institution or other source category. role_id / counterparty_id (FK pair, child row) | R | One party may have several roles; avoid duplicate party records. organisation_id (FK M01) | C | Link if the party is also an existing government agency. contact_reference (source FK) | O | Existing approved address/contact record, not payment authority. Create/modify through F01 under Maker-Checker-Approver; approved changes apply prospectively and preserve historical references. | K6: M02 | N6: F01-F04, AC01, C01, R19-R20 | O6: Must | P6: 1 - Foundation and Configuration | Q6: Section 8.3.2 | R6: Ready for Review
A7: 0 | B7: Data Foundation and Traceability | C7: DF01 | D7: Master data and shared-source integration | E7: DF01-US03 | F7: Configuration Administrator | G7: Data foundation | H7: As a Configuration Administrator, I want to maintain or integrate M03 - Country / residency / existing country; residency_rule_reference, so that approved debt functions use one controlled and traceable value source. | I7: AC1. Given M03 is implemented, when a value is created, fetched or synchronised, then the following ownership shall be enforced: Existing shared source. AC2. Given a record is entered or received, when it is validated, then every field, required/conditional flag, permitted value and validation documented for M03 in the Data Objects sheet shall be enforced. AC3. Given the object is source-owned, when Debt Management fetches or displays the record, then the original source ID shall be reused, source attributes shall remain read-only and no duplicate master shall be created. AC4. Given a debt-specific value is created or modified, when it is submitted for activation, then F01 Maker-Checker-Approver, effective dates, active/inactive status and immutable history shall apply before the value is used. AC5. Given an approved value becomes effective, when an applicable function loads its selectors or validations, then the value shall be available only in the applicable functions: Derived from Annexure B and referenced feature metadata. | J7: Effective-dated master/reference data; source-owned IDs are reused where identified. country_code (text) | R | Approved country code, e.g., IN, NP, JP. country_name (text) | R | Source country label. reporting_country_id (FK) | R | Country of the reporting entity; drives resident/non-resident comparison. classification_rule_id (FK configuration) | R | Approved country-specific residency rule; no currency-only inference. Create/modify through F01 under Maker-Checker-Approver; approved changes apply prospectively and preserve historical references. | K7: M03 | N7: F01-F04, AC01, C01, R19-R20 | O7: Must | P7: 1 - Foundation and Configuration | Q7: Section 8.3.3 | R7: Ready for Review
A8: 0 | B8: Data Foundation and Traceability | C8: DF01 | D8: Master data and shared-source integration | E8: DF01-US04 | F8: Configuration Administrator | G8: Data foundation | H8: As a Configuration Administrator, I want to maintain or integrate M04 - Currency / existing currency, so that approved debt functions use one controlled and traceable value source. | I8: AC1. Given M04 is implemented, when a value is created, fetched or synchronised, then the following ownership shall be enforced: Existing shared source. AC2. Given a record is entered or received, when it is validated, then every field, required/conditional flag, permitted value and validation documented for M04 in the Data Objects sheet shall be enforced. AC3. Given the object is source-owned, when Debt Management fetches or displays the record, then the original source ID shall be reused, source attributes shall remain read-only and no duplicate master shall be created. AC4. Given a debt-specific value is created or modified, when it is submitted for activation, then F01 Maker-Checker-Approver, effective dates, active/inactive status and immutable history shall apply before the value is used. AC5. Given an approved value becomes effective, when an applicable function loads its selectors or validations, then the value shall be available only in the applicable functions: Derived from Annexure B and referenced feature metadata. | J8: Effective-dated master/reference data; source-owned IDs are reused where identified. currency_code (text) | R | USD, EUR, JPY or the configured local currency. currency_name (text) | R | Source display name. decimal_precision (integer) | R | Example USD=2; JPY=0, from approved source. rounding_rule_id (FK) | R | Approved rounding policy for currency amounts. reporting_entity_id / local_currency_id (FK pair, child row) | R | One reporting/base currency per entity and effective period. Create/modify through F01 under Maker-Checker-Approver; approved changes apply prospectively and preserve historical references. | K8: M04 | N8: F01-F04, AC01, C01, R19-R20 | O8: Must | P8: 1 - Foundation and Configuration | Q8: Section 8.3.4 | R8: Ready for Review
A9: 0 | B9: Data Foundation and Traceability | C9: DF01 | D9: Master data and shared-source integration | E9: DF01-US05 | F9: Configuration Administrator | G9: Data foundation | H9: As a Configuration Administrator, I want to maintain or integrate M05 - Project / Program / existing project_program; existing component, so that approved debt functions use one controlled and traceable value source. | I9: AC1. Given M05 is implemented, when a value is created, fetched or synchronised, then the following ownership shall be enforced: Existing shared source. AC2. Given a record is entered or received, when it is validated, then every field, required/conditional flag, permitted value and validation documented for M05 in the Data Objects sheet shall be enforced. AC3. Given the object is source-owned, when Debt Management fetches or displays the record, then the original source ID shall be reused, source attributes shall remain read-only and no duplicate master shall be created. AC4. Given a debt-specific value is created or modified, when it is submitted for activation, then F01 Maker-Checker-Approver, effective dates, active/inactive status and immutable history shall apply before the value is used. AC5. Given an approved value becomes effective, when an applicable function loads its selectors or validations, then the value shall be available only in the applicable functions: Derived from Annexure B and referenced feature metadata. | J9: Effective-dated master/reference data; source-owned IDs are reused where identified. project_program_id (source FK) | R | PRJ001 or PRG001 from the separate existing list. record_type (source value) | R | Project or Program. parent_program_id (source FK) | C | PRG001 for a project within a program. component_id (source FK, child row) | C | CMP001; only if the source provides components. responsible_organisation_id (FK M01) | R | Source agency; read-only in Debt Management. start_date / end_date (date) | R / C | Source-approved project duration. approved_cost / cost_currency_id (decimal / FK M04) | C | Source cost; not automatically the debt allocation. lifecycle_status / source_version (source fields) | R | Fetched status/version; inactive projects blocked from new links. Create/modify through F01 under Maker-Checker-Approver; approved changes apply prospectively and preserve historical references. | K9: M05 | N9: F01-F04, AC01, C01, R19-R20 | O9: Must | P9: 1 - Foundation and Configuration | Q9: Section 8.3.5 | R9: Ready for Review
A10: 0 | B10: Data Foundation and Traceability | C10: DF01 | D10: Master data and shared-source integration | E10: DF01-US06 | F10: Configuration Administrator | G10: Data foundation | H10: As a Configuration Administrator, I want to maintain or integrate M06 - Fund source / existing fund_source, so that approved debt functions use one controlled and traceable value source. | I10: AC1. Given M06 is implemented, when a value is created, fetched or synchronised, then the following ownership shall be enforced: Existing shared source. AC2. Given a record is entered or received, when it is validated, then every field, required/conditional flag, permitted value and validation documented for M06 in the Data Objects sheet shall be enforced. AC3. Given the object is source-owned, when Debt Management fetches or displays the record, then the original source ID shall be reused, source attributes shall remain read-only and no duplicate master shall be created. AC4. Given a debt-specific value is created or modified, when it is submitted for activation, then F01 Maker-Checker-Approver, effective dates, active/inactive status and immutable history shall apply before the value is used. AC5. Given an approved value becomes effective, when an applicable function loads its selectors or validations, then the value shall be available only in the applicable functions: Derived from Annexure B and referenced feature metadata. | J10: Effective-dated master/reference data; source-owned IDs are reused where identified. fund_source_id (source FK) | R | FS001. fund_source_category (source FK) | R | Budgetary resources; External loan; Domestic borrowing; Grant; Government counterpart funding. parent_fund_source_id (FK) | C | Source funding hierarchy. owner_organisation_id (FK M01) | C | Entity scope where required. coa_dimension_value_id (FK M07 dimension) | C | Existing funding-segment value, where configured. Create/modify through F01 under Maker-Checker-Approver; approved changes apply prospectively and preserve historical references. | K10: M06 | N10: F01-F04, AC01, C01, R19-R20 | O10: Must | P10: 1 - Foundation and Configuration | Q10: Section 8.3.6 | R10: Ready for Review
A11: 0 | B11: Data Foundation and Traceability | C11: DF01 | D11: Master data and shared-source integration | E11: DF01-US07 | F11: Configuration Administrator | G11: Data foundation | H11: As a Configuration Administrator, I want to maintain or integrate M07 - CoA / HoA / existing chart_of_accounts; account_dimension; account_basis_policy, so that approved debt functions use one controlled and traceable value source. | I11: AC1. Given M07 is implemented, when a value is created, fetched or synchronised, then the following ownership shall be enforced: Existing shared source. AC2. Given a record is entered or received, when it is validated, then every field, required/conditional flag, permitted value and validation documented for M07 in the Data Objects sheet shall be enforced. AC3. Given the object is source-owned, when Debt Management fetches or displays the record, then the original source ID shall be reused, source attributes shall remain read-only and no duplicate master shall be created. AC4. Given a debt-specific value is created or modified, when it is submitted for activation, then F01 Maker-Checker-Approver, effective dates, active/inactive status and immutable history shall apply before the value is used. AC5. Given an approved value becomes effective, when an applicable function loads its selectors or validations, then the value shall be available only in the applicable functions: Derived from Annexure B and referenced feature metadata. | J11: Effective-dated master/reference data; source-owned IDs are reused where identified. account_id / account_code (source ID / text) | R | Existing account reference; illustrative label BANK_CONTROL, not a prescribed code. account_name / account_class (source fields) | R | Bank, Borrowing liability, Lending receivable, Interest, Grant or expenditure classification. parent_account_id / posting_allowed (FK / boolean) | C / R | Source hierarchy and leaf/postable restriction. dimension_id / dimension_value_id (FK pair, child row) | C | Configured organisation, fund, project, economic or other dimensions. entity_id / accounting_basis_id (FK M01 / M32) | R | Use existing cash/accrual/hybrid applicability. component_id / recognition_basis_id (FK M23 / M32, child row) | C | Hybrid component-specific recognition; no second chart. effective_dates / source_status (source fields) | R | Only valid, permitted account combinations may be posted. Create/modify through F01 under Maker-Checker-Approver; approved changes apply prospectively and preserve historical references. | K11: M07 | N11: F01-F04, AC01, C01, R19-R20 | O11: Must | P11: 1 - Foundation and Configuration | Q11: Section 8.3.7 | R11: Ready for Review
A12: 0 | B12: Data Foundation and Traceability | C12: DF01 | D12: Master data and shared-source integration | E12: DF01-US08 | F12: Configuration Administrator | G12: Data foundation | H12: As a Configuration Administrator, I want to maintain or integrate M08 - Bank and account / existing bank; bank_account, so that approved debt functions use one controlled and traceable value source. | I12: AC1. Given M08 is implemented, when a value is created, fetched or synchronised, then the following ownership shall be enforced: Existing shared source. AC2. Given a record is entered or received, when it is validated, then every field, required/conditional flag, permitted value and validation documented for M08 in the Data Objects sheet shall be enforced. AC3. Given the object is source-owned, when Debt Management fetches or displays the record, then the original source ID shall be reused, source attributes shall remain read-only and no duplicate master shall be created. AC4. Given a debt-specific value is created or modified, when it is submitted for activation, then F01 Maker-Checker-Approver, effective dates, active/inactive status and immutable history shall apply before the value is used. AC5. Given an approved value becomes effective, when an applicable function loads its selectors or validations, then the value shall be available only in the applicable functions: Derived from Annexure B and referenced feature metadata. | J12: Effective-dated master/reference data; source-owned IDs are reused where identified. bank_id / branch_id (source FK) | R / C | Approved bank and branch. bank_account_id (source FK) | R | BA001; stable ID, with masked display number. owner_party_id / owner_entity_id (FK M02 / M01) | C | At least the applicable legal account owner. currency_id (FK M04) | R | Account currency. account_purpose (source FK) | R | Treasury, special/designated account, creditor or recipient account. bank_coa_id (FK M07) | C | Required for a government-owned cash account that posts to GL. settlement_channel_id / source_status (source fields) | C / R | Approved Treasury/bank channel and active status. Create/modify through F01 under Maker-Checker-Approver; approved changes apply prospectively and preserve historical references. | K12: M08 | N12: F01-F04, AC01, C01, R19-R20 | O12: Must | P12: 1 - Foundation and Configuration | Q12: Section 8.3.8 | R12: Ready for Review
A13: 0 | B13: Data Foundation and Traceability | C13: DF01 | D13: Master data and shared-source integration | E13: DF01-US09 | F13: Configuration Administrator | G13: Data foundation | H13: As a Configuration Administrator, I want to maintain or integrate M09 - Financial calendar / existing financial_year; accounting_period; business_calendar, so that approved debt functions use one controlled and traceable value source. | I13: AC1. Given M09 is implemented, when a value is created, fetched or synchronised, then the following ownership shall be enforced: Existing shared source. AC2. Given a record is entered or received, when it is validated, then every field, required/conditional flag, permitted value and validation documented for M09 in the Data Objects sheet shall be enforced. AC3. Given the object is source-owned, when Debt Management fetches or displays the record, then the original source ID shall be reused, source attributes shall remain read-only and no duplicate master shall be created. AC4. Given a debt-specific value is created or modified, when it is submitted for activation, then F01 Maker-Checker-Approver, effective dates, active/inactive status and immutable history shall apply before the value is used. AC5. Given an approved value becomes effective, when an applicable function loads its selectors or validations, then the value shall be available only in the applicable functions: Derived from Annexure B and referenced feature metadata. | J13: Effective-dated master/reference data; source-owned IDs are reused where identified. financial_year_id (source FK) | R | FY2026, using the configured year boundaries. period_id / start_date / end_date (FK / dates) | R | P2026-08 / configured period start and end. entity_id / calendar_id (FK) | R | Calendar for the accounting entity. period_status (system enum) | R | Open, Closing or Closed; controlled by authorised period operations. business_date (date) | R | Current processing date from the approved calendar service. holiday_date / holiday_name (date / text, child row) | C | Configured local holidays used by payment-date rules. adjustment_period_id (FK) | C | Authorised period for prior-period corrections. Create/modify through F01 under Maker-Checker-Approver; approved changes apply prospectively and preserve historical references. | K13: M09 | N13: F01-F04, AC01, C01, R19-R20 | O13: Must | P13: 1 - Foundation and Configuration | Q13: Section 8.3.9 | R13: Ready for Review
A14: 0 | B14: Data Foundation and Traceability | C14: DF01 | D14: Master data and shared-source integration | E14: DF01-US10 | F14: Configuration Administrator | G14: Data foundation | H14: As a Configuration Administrator, I want to maintain or integrate M10 - Users, roles and designations / existing user; role; designation; user_role_scope, so that approved debt functions use one controlled and traceable value source. | I14: AC1. Given M10 is implemented, when a value is created, fetched or synchronised, then the following ownership shall be enforced: Existing shared source. AC2. Given a record is entered or received, when it is validated, then every field, required/conditional flag, permitted value and validation documented for M10 in the Data Objects sheet shall be enforced. AC3. Given the object is source-owned, when Debt Management fetches or displays the record, then the original source ID shall be reused, source attributes shall remain read-only and no duplicate master shall be created. AC4. Given a debt-specific value is created or modified, when it is submitted for activation, then F01 Maker-Checker-Approver, effective dates, active/inactive status and immutable history shall apply before the value is used. AC5. Given an approved value becomes effective, when an applicable function loads its selectors or validations, then the value shall be available only in the applicable functions: Derived from Annexure B and referenced feature metadata. | J14: Effective-dated master/reference data; source-owned IDs are reused where identified. user_id (source FK) | R | USR001; no credential copies in Debt Management. role_id (source FK) | R | Maker, Checker, Approver, Viewer or authorised administrator. designation_id (source FK) | C | Debt Officer / Finance Controller; configurable source designation. organisation_scope_id (FK M01) | R | Permitted entity or hierarchy scope. user_id / role_id / validity (child assignment) | R | Effective-dated role assignment; one user may have several scoped roles. account_status (source enum) | R | Source active/disabled state. delegation_reference (source FK) | C | Approved temporary delegation, subject to C01 limits. Create/modify through F01 under Maker-Checker-Approver; approved changes apply prospectively and preserve historical references. | K14: M10 | N14: F01-F04, AC01, C01, R19-R20 | O14: Must | P14: 1 - Foundation and Configuration | Q14: Section 8.3.10 | R14: Ready for Review
A15: 0 | B15: Data Foundation and Traceability | C15: DF01 | D15: Master data and shared-source integration | E15: DF01-US11 | F15: Configuration Administrator | G15: Data foundation | H15: As a Configuration Administrator, I want to maintain or integrate M11 - Project expenditure category / existing expenditure_category; category_coa_map, so that approved debt functions use one controlled and traceable value source. | I15: AC1. Given M11 is implemented, when a value is created, fetched or synchronised, then the following ownership shall be enforced: Existing shared source. AC2. Given a record is entered or received, when it is validated, then every field, required/conditional flag, permitted value and validation documented for M11 in the Data Objects sheet shall be enforced. AC3. Given the object is source-owned, when Debt Management fetches or displays the record, then the original source ID shall be reused, source attributes shall remain read-only and no duplicate master shall be created. AC4. Given a debt-specific value is created or modified, when it is submitted for activation, then F01 Maker-Checker-Approver, effective dates, active/inactive status and immutable history shall apply before the value is used. AC5. Given an approved value becomes effective, when an applicable function loads its selectors or validations, then the value shall be available only in the applicable functions: Derived from Annexure B and referenced feature metadata. | J15: Effective-dated master/reference data; source-owned IDs are reused where identified. category_id (source FK) | R | EC001. parent_category_id (source FK) | C | Source category hierarchy. category_name (source text) | R | Works; Goods; Consultancy; Training; Operating costs. economic_account_id (FK M07, child row) | C | Existing economic classification or expenditure account. source_system_id / source_category_key (source fields) | R | Stable source key for project/expenditure integration. Create/modify through F01 under Maker-Checker-Approver; approved changes apply prospectively and preserve historical references. | K15: M11 | N15: F01-F04, AC01, C01, R19-R20 | O15: Must | P15: 1 - Foundation and Configuration | Q15: Section 8.3.11 | R15: Ready for Review
A16: 0 | B16: Data Foundation and Traceability | C16: DF01 | D16: Master data and shared-source integration | E16: DF01-US12 | F16: Configuration Administrator | G16: Data foundation | H16: As a Configuration Administrator, I want to maintain or integrate M12 - Instrument Type Master / debt_instrument_type, so that approved debt functions use one controlled and traceable value source. | I16: AC1. Given M12 is implemented, when a value is created, fetched or synchronised, then the following ownership shall be enforced: Configuration module. AC2. Given a record is entered or received, when it is validated, then every field, required/conditional flag, permitted value and validation documented for M12 in the Data Objects sheet shall be enforced. AC3. Given the object is source-owned, when Debt Management fetches or displays the record, then the original source ID shall be reused, source attributes shall remain read-only and no duplicate master shall be created. AC4. Given a debt-specific value is created or modified, when it is submitted for activation, then F01 Maker-Checker-Approver, effective dates, active/inactive status and immutable history shall apply before the value is used. AC5. Given an approved value becomes effective, when an applicable function loads its selectors or validations, then the value shall be available only in the applicable functions: Derived from Annexure B and referenced feature metadata. | J16: Effective-dated master/reference data; source-owned IDs are reused where identified. type_code (text) | R | LOAN; SECURITY; GRANT; GUARANTEE. type_name (text) | R | Loan; Debt security; Grant; Guarantee. subtype_master_reference (configuration reference) | R | Loan→M13; Security→M15; Grant→M26; Guarantee→M13 plus M27. portfolio_bucket (configured value) | R | Borrowing; Lending; Grant; Guarantee exposure, as applicable to transaction role. menu_route / form_definition_id (configuration reference) | R | Approved screen and applicable field set. Create/modify through F01 under Maker-Checker-Approver; approved changes apply prospectively and preserve historical references. | K16: M12 | N16: F01-F04, AC01, C01, R19-R20 | O16: Must | P16: 1 - Foundation and Configuration | Q16: Section 8.3.12 | R16: Ready for Review
... A60: 0 | B60: Data Foundation and Traceability | C60: DF02 | D60: Effective-dated configuration and control tables | E60: DF02-US13 | F60: Configuration Administrator | G60: Data foundation | H60: As a Configuration Administrator, I want to configure C13 - government_lending_scheme; scheme_condition, so that debt processing uses approved rules without changing the application core. | I60: AC1. Given C13 is configured, when a rule row is entered or imported, then every field, required/conditional flag, sample rule constraint and validation documented for C13 in the Data Objects sheet shall be enforced. AC2. Given a rule is created or changed, when it is submitted, then Maker-Checker-Approver, authority, test/simulation and effective-date controls shall apply. AC3. Given a rule version is approved, when an eligible future or open transaction is processed, then the transaction shall retain the exact version used and settled transactions or posted entries shall not be recalculated silently. AC4. Given the rule is effective, when an applicable function evaluates its controls, then it shall use the rule in the applicable functions: F35-F36 AC5. Given an eligible source event occurs, when C13 rule processing runs, then the system shall perform every trigger and action documented for C13 in the Data Objects sheet. | J60: Agreement/product/rule configuration for advanced loan and central-bank facility functions. C13 government_lending_scheme; scheme_condition: scheme_id/version (R); sanction authority/reference (R); M41 purpose, borrower category, funding source and CoA mapping (R); budget requirement (R); rate/fees/tenor/grace defaults (C); release/verification/utilisation conditions (child C); recovery/offset authority (C); effective dates (R). Example: SCHEME01 / State capital investment / sanction-specific terms. Maker creates/tests the rule, Checker validates formula and dependencies, Approver activates the effective version; actual events retain the version used. | K60: C13 | N60: F01-F04, AC01, C01, R19-R20 | O60: Must | P60: 1 - Foundation and Configuration | Q60: Section 13.2 / Annexure D | R60: Ready for Review
A61: 0 | B61: Data Foundation and Traceability | C61: DF03 | D61: Event registers, balances and traceability | E61: DF03-US01 | F61: System | G61: Data foundation | H61: As the system, I want to populate R01 - Loan Borrowing Register from approved source events, so that balances and transaction history are complete, deduplicated and traceable. | I61: AC1. Given R01 is implemented, when its schema and processing grain are reviewed, then they shall conform to: One borrowing agreement, its effective terms versions and one movement per eligible source-event line. Suggested tables: loan_borrowing; loan_terms_version; loan_borrowing_movement. AC2. Given a record or movement is written, when field validation runs, then every field, required/conditional flag and validation documented for R01 in the Data Objects sheet shall be enforced. AC3. Given an eligible event occurs, when R01 register processing runs, then every trigger, register action and linked update documented for R01 in the Data Objects sheet shall be performed. AC4. Given the same approved event is retried, when the idempotency key is evaluated, then duplicate movements shall be prevented and derived balances shall reconcile to immutable source lines. AC5. Given a correction, reversal or failed destination occurs, when the linked action is processed, then the original event shall remain available and the action and destination status shall be recorded through R19/R20. | J61: One borrowing agreement, its effective terms versions and one movement per eligible source-event line. Suggested tables: loan_borrowing; loan_terms_version; loan_borrowing_movement. loan_id / agreement_number (ID / text) | R | L001 / AGR-2026-001; unique by creditor/entity/agreement policy. creditor_id / borrower_entity_id (FK M02 / M01) | R | Government as borrower; not a subsidiary receivable. classification_id / arrangement_id / fund_source_id (FK M13 / M14 / M06) | R | External / Direct borrowing / External loan, illustrative. agreement_date / effectiveness_date / maturity_date (dates) | R | Signed, effective and final maturity dates. original_limit / approved_limit / cancelled_undrawn (decimals) | R | Example 1,000,000 / 1,000,000 / 0 in agreement currency. terms_version_id / calculation_rule_id (FK / C03) | R | Interest, repayment and charge rules; supporting terms fields in 9.23. movement_type / principal_movement (event code / decimal) | C | Drawdown +100,000; settled principal -10,000; other changes separately classified. cumulative_drawn / cumulative_principal_paid (derived decimals) | R | Derived from qualified R07 drawdowns and R10 principal settlements. undrawn_available / contractual_outstanding (derived decimals) | R | Agreement-currency available commitment and legal principal; adjusted for approved cancellation/restructuring, not FX translation. gross_carrying_amount / carrying_adjustment (derived decimals) | C | Accounting measurement separately from contractual principal; linked to R13/R18. last_schedule_version / lifecycle_status (FK R08 / system enum) | R | Current eligible schedule; Active, Matured-unpaid or Closed as applicable. F05-D/E A.5-A.6: agreement effective | CREATE agreement and approved terms version; establish authorised and undrawn limits. Do not create drawn principal. | R06 allocations; R08 schedule/forecast; R20 audit. F17 / AC03-AC04: approved evidenced drawdown | APPEND drawdown movement; DERIVE cumulative drawn, undrawn availability and contractual principal. | R07; R08-R09; eligible R17; R18-R19. F19 / AC03-AC04: principal settlement confirmed | APPEND principal repayment only for the settled principal component; DERIVE outstanding. Interest-only settlement leaves principal unchanged. | R08-R10, R12; R18-R19; forecasts/reports. F05 B / F22 / AC09: approved amendment or restructuring | VERSION terms/limit; APPEND authorised non-cash principal changes with action reference. New borrowing/repaid borrowing remain separate for refinancing. | R08, R14; affected subsidiaries flagged; accounting as configured. AC22 / F30: valuation, correction or closure | LINK R13 carrying-value/FX adjustment without changing legal principal; REVERSE/ADJUST erroneous movement; close only after reconciliation. | R13, R18-R20; eligible schedules and current reporting views. | L61: R01 | N61: F01-F04, AC01, C01, R19-R20 | O61: Must | P61: 1 - Foundation and Configuration | Q61: Section 9.2 | R61: Ready for Review
